INFO:root:using device: cpu
INFO:root:processing subjects: [1, 5, 6, 7, 8]
INFO:root:Training data loader called. len - 5
INFO:root:processing subjects: [9, 11]
INFO:root:Validation data loader called. len - 5
INFO:root:Start training procedure
2d_2_3d Epoch: 1 [0/5 (0%)]	Loss: 1.1904	ReCon: 1.1903	KLD: 0.0799
2d_2_3d Validation: 		Loss: 1.0008 	ReCon: 1.0008 	KLD: 0.0004
Traceback (most recent call last):
  File "/home/datta/lab/HPE3D/src/train.py", line 186, in <module>
    main()
  File "/home/datta/lab/HPE3D/src/train.py", line 120, in main
    evaluate_poses(config, model, val_loader, epoch, vae_type)
  File "/home/datta/lab/HPE3D/src/trainer.py", line 126, in evaluate_poses
    f"{os.path.dirname(os.path.abspath(__file__))}/data/norm_stats._h36m17_911.h5", 'r')
  File "/home/datta/miniconda3/envs/ml/lib/python3.7/site-packages/h5py/_hl/files.py", line 312, in __init__
    fid = make_fid(name, mode, userblock_size, fapl, swmr=swmr)
  File "/home/datta/miniconda3/envs/ml/lib/python3.7/site-packages/h5py/_hl/files.py", line 142, in make_fid
    fid = h5f.open(name, flags, fapl=fapl)
  File "h5py/_objects.pyx", line 54, in h5py._objects.with_phil.wrapper
  File "h5py/_objects.pyx", line 55, in h5py._objects.with_phil.wrapper
  File "h5py/h5f.pyx", line 78, in h5py.h5f.open
OSError: Unable to open file (unable to open file: name = '/home/datta/lab/HPE3D/src/data/norm_stats._h36m17_911.h5', errno = 2, error message = 'No such file or directory', flags = 0, o_flags = 0)
